Workbook

Sheet المنتجات
A1: منتجات تيست السوق العراقي · Taager
A2: الأسعار بالدينار العراقي كما في صفحات المنتجات · المنتجات المتشابهة مجمّعة تحت بعض ومرتبة من الأرخص للأغلى · سكرين شوت 26-10-2026
A4: # | B4: اسم المنتج | C4: كود المنتج SKU | D4: السعر (د.ع) | E4: أقل سعر بيع (د.ع) | F4: أقل ربح (د.ع) | G4: خصم القطعتين | H4: خصومات الكمية حتى | I4: نسبة التأكيد | J4: تقييم التأكيد | K4: نسبة التوصيل | L4: تقييم التوصيل | M4: التسليم المتوقع (تأكيد × توصيل) | N4: ملاحظات | O4: السكرين شوت
A5: =" المكانس الكهربائية · "&COUNTA(B6:B13)&" منتجات · السعر من "&TEXT(MIN(D6:D13),"#,##0")&" إلى "&TEXT(MAX(D6:D13),"#,##0")&" د.ع" -> المكانس الكهربائية · 8 منتجات · السعر من 18,000 إلى 101,000 د.ع
A6: 1 | B6: مكنسة تنظيف منزلي Acarid Remover | C6: IQ030101ACRI99 | D6: 18000 | E6: 21000 | F6: 3000 | G6: 0.03 | H6: 4 | I6: 0.83 | J6: ممتاز | K6: 0.71 | L6: ممتاز | M6: =IF(AND(ISNUMBER(I6),ISNUMBER(K6)),I6*K6,"") -> 0.5893 | O6: 143306
A7: 2 | B7: المكنسة القابلة لإعادة الشحن الحديثة 3 في 1 | C7: IQ030303MSSK99 | D7: 33000 | E7: 36000 | F7: 3000 | I7: 0.79 | J7: ممتاز | L7: — | M7: =IF(AND(ISNUMBER(I7),ISNUMBER(K7)),I7*K7,"") | O7: 143243
A8: 3 | B8: المكنسة القابلة لإعادة الشحن 3 في 1 ضمان 6 أشهر | C8: IQ030303MKNN99 | D8: 34000 | E8: 34000 | F8: 0 | I8: 0.61 | J8: ممتاز | L8: — | M8: =IF(AND(ISNUMBER(I8),ISNUMBER(K8)),I8*K8,"") | O8: 143435
A9: 4 | B9: مكنسة روبوت Smart Home ضمان 6 أشهر | C9: IQ030303ROHM99 | D9: 36000 | E9: 39000 | F9: 3000 | I9: 0.63 | J9: ممتاز | L9: — | M9: =IF(AND(ISNUMBER(I9),ISNUMBER(K9)),I9*K9,"") | O9: 143410
A10: 5 | B10: مكنسة كهربائية لاسلكية محمولة 2 في 1 ضمان عام | C10: IQ030303MALA99 | D10: 45000 | E10: 47000 | F10: 2000 | J10: — | L10: — | M10: =IF(AND(ISNUMBER(I10),ISNUMBER(K10)),I10*K10,"") | N10: مازالت المنصة تجمع إحصائيات المنتج | O10: 143558
A11: 6 | B11: المكنسة الكهربائية الحديثة ضمان 6 أشهر | C11: IQ030303ACSS99 | D11: 45500 | E11: 45500 | F11: 0 | G11: 0.29 | H11: 4 | J11: — | L11: — | M11: =IF(AND(ISNUMBER(I11),ISNUMBER(K11)),I11*K11,"") | N11: مازالت المنصة تجمع إحصائيات المنتج | O11: 143607
A12: 7 | B12: المكنسة الكهربائية اللاسلكية متعددة الاستخدامات GUFY | C12: IQ030304GUFY99 | D12: 79000 | E12: 82000 | F12: 3000 | J12: — | L12: — | M12: =IF(AND(ISNUMBER(I12),ISNUMBER(K12)),I12*K12,"") | N12: مازالت المنصة تجمع إحصائيات المنتج | O12: 143537
A13: 8 | B13: مكنسة تنظيف السجاد و المفروشات جاف ورطب | C13: IQ030304TAZT99 | D13: 101000 | E13: 101000 | F13: 0 | J13: — | L13: — | M13: =IF(AND(ISNUMBER(I13),ISNUMBER(K13)),I13*K13,"") | N13: مازالت المنصة تجمع إحصائيات المنتج | O13: 143511
A15: =" أجهزة التنظيف بالبخار · "&COUNTA(B16:B17)&" منتجات · السعر من "&TEXT(MIN(D16:D17),"#,##0")&" إلى "&TEXT(MAX(D16:D17),"#,##0")&" د.ع" -> أجهزة التنظيف بالبخار · 2 منتجات · السعر من 37,000 إلى 47,000 د.ع
A16: 9 | B16: جهاز تنظيف بالبخار بالضغط العالي | C16: IQ030401BOHK99 | D16: 37000 | E16: 40000 | F16: 3000 | G16: 0.12 | H16: 4 | I16: 0.5 | J16: جيد | K16: 0.62 | L16: ممتاز | M16: =IF(AND(ISNUMBER(I16),ISNUMBER(K16)),I16*K16,"") -> 0.31 | O16: 143015
A17: 10 | B17: جهاز تنظيف بالبخار بالضغط العالي شكل دائري | C17: IQ030303BOJH99 | D17: 47000 | E17: 50000 | F17: 3000 | J17: — | L17: — | M17: =IF(AND(ISNUMBER(I17),ISNUMBER(K17)),I17*K17,"") | N17: مازالت المنصة تجمع إحصائيات المنتج | O17: 143633
A19: =" محضرات الطعام والخلاطات · "&COUNTA(B20:B23)&" منتجات · السعر من "&TEXT(MIN(D20:D23),"#,##0")&" إلى "&TEXT(MAX(D20:D23),"#,##0")&" د.ع" -> محضرات الطعام والخلاطات · 4 منتجات · السعر من 26,500 إلى 88,500 د.ع
A20: 11 | B20: خلاط Silver Crest + طاحونة ضمان 6 أشهر | C20: IQ030401CILV99 | D20: 26500 | E20: 28500 | F20: 2000 | G20: 0.23 | H20: 2 | I20: 0.56 | J20: جيد | K20: 0.62 | L20: ممتاز | M20: =IF(AND(ISNUMBER(I20),ISNUMBER(K20)),I20*K20,"") -> 0.3472 | O20: 143453
A21: 12 | B21: محضرة الطعام Olympia أكبر حجم 8 لتر | C21: IQ030401ALMN99 | D21: 39000 | E21: 41000 | F21: 2000 | G21: 0.31 | H21: 3 | I21: 0.53 | J21: جيد | K21: 0.69 | L21: ممتاز | M21: =IF(AND(ISNUMBER(I21),ISNUMBER(K21)),I21*K21,"") -> 0.3657 | O21: 143359
A22: 13 | B22: محضرة الطعام Olympia 8 لتر + ضمان 6 شهور (عرض مجمّع) | C22: IQ030501MNOI99 | D22: 43000 | E22: 45000 | F22: 2000 | J22: — | L22: — | M22: =IF(AND(ISNUMBER(I22),ISNUMBER(K22)),I22*K22,"") | N22: مازالت المنصة تجمع إحصائيات المنتج · عرض مجمّع: IQ030401ALMN99 + IQ030101DFLM99 | O22: 143213
A23: 14 | B23: محضرة الطعام المتكاملة 10 في 1 | C23: IQ030401ROPM99 | D23: 88500 | E23: 90500 | F23: 2000 | G23: 0.11 | H23: 3 | J23: — | L23: — | M23: =IF(AND(ISNUMBER(I23),ISNUMBER(K23)),I23*K23,"") | N23: مازالت المنصة تجمع إحصائيات المنتج | O23: 143100
A25: =" المفارم والقطاعات · "&COUNTA(B26:B30)&" منتجات · السعر من "&TEXT(MIN(D26:D30),"#,##0")&" إلى "&TEXT(MAX(D26:D30),"#,##0")&" د.ع" -> المفارم والقطاعات · 5 منتجات · السعر من 21,000 إلى 59,000 د.ع
A26: 15 | B26: مفرمة اللحوم و الخضروات الحديثة 3 لتر | C26: IQ030401MOGH99 | D26: 21000 | E26: 24000 | F26: 3000 | G26: 0.05 | H26: 4 | I26: 0.51 | J26: جيد | L26: — | M26: =IF(AND(ISNUMBER(I26),ISNUMBER(K26)),I26*K26,"") | O26: 143032
A27: 16 | B27: قطاعة الخضروات الحديثة | C27: IQ030401ATTA99 | D27: 29000 | E27: 32000 | F27: 3000 | G27: 0.09 | H27: 4 | I27: 0.63 | J27: ممتاز | K27: 0.67 | L27: ممتاز | M27: =IF(AND(ISNUMBER(I27),ISNUMBER(K27)),I27*K27,"") -> 0.4221 | O27: 143232
A28: 17 | B28: قطاعة الخضروات الحديثة تعمل بالشحن Denx | C28: IQ030401KHOD99 | D28: 33000 | E28: 35000 | F28: 2000 | J28: — | L28: — | M28: =IF(AND(ISNUMBER(I28),ISNUMBER(K28)),I28*K28,"") | N28: مازالت المنصة تجمع إحصائيات المنتج | O28: 143654
A29: 18 | B29: محضرة الخضروات الحديثة | C29: IQ030401ATMO99 | D29: 40500 | E29: 42500 | F29: 2000 | H29: 4 | I29: 0.56 | J29: جيد | K29: 0.58 | L29: ممتاز | M29: =IF(AND(ISNUMBER(I29),ISNUMBER(K29)),I29*K29,"") -> 0.3248 | O29: 143421
A30: 19 | B30: مفرمة اللحوم الكهربائية ENZO | C30: IQ030401ENZO99 | D30: 59000 | E30: 59000 | F30: 0 | J30: — | L30: — | M30: =IF(AND(ISNUMBER(I30),ISNUMBER(K30)),I30*K30,"") | N30: مازالت المنصة تجمع إحصائيات المنتج | O30: 143518
A32: =" أجهزة مطبخ أخرى · "&COUNTA(B33:B34)&" منتجات · السعر من "&TEXT(MIN(D33:D34),"#,##0")&" إلى "&TEXT(MAX(D33:D34),"#,##0")&" د.ع" -> أجهزة مطبخ أخرى · 2 منتجات · السعر من 29,000 إلى 60,000 د.ع
A33: 20 | B33: جدر تسوية الطعام الكهربائيه | C33: IQ030404ZPY099 | D33: 29000 | E33: 31000 | F33: 2000 | J33: — | L33: — | M33: =IF(AND(ISNUMBER(I33),ISNUMBER(K33)),I33*K33,"") | N33: مازالت المنصة تجمع إحصائيات المنتج | O33: 143138
A34: 21 | B34: موقد 4 عيون بستاند | C34: IQ030401MOKD99 | D34: 60000 | E34: 62000 | F34: 2000 | J34: — | L34: — | M34: =IF(AND(ISNUMBER(I34),ISNUMBER(K34)),I34*K34,"") | N34: مازالت المنصة تجمع إحصائيات المنتج | O34: 142943
A36: =" منزل متنوع · "&COUNTA(B37:B41)&" منتجات · السعر من "&TEXT(MIN(D37:D41),"#,##0")&" إلى "&TEXT(MAX(D37:D41),"#,##0")&" د.ع" -> منزل متنوع · 5 منتجات · السعر من 11,500 إلى 59,000 د.ع
A37: 22 | B37: غالق الأبواب السحري | C37: IQ030303KHLK99 | D37: 11500 | E37: 11500 | F37: 0 | G37: 0.52 | H37: 4 | J37: — | L37: — | M37: =IF(AND(ISNUMBER(I37),ISNUMBER(K37)),I37*K37,"") | N37: مازالت المنصة تجمع إحصائيات المنتج | O37: 143746
A38: 23 | B38: زاوية حمام 4 دور | C38: IQ030106ZAWW99 | D38: 16000 | E38: 18000 | F38: 2000 | G38: 0.12 | H38: 4 | J38: — | L38: — | M38: =IF(AND(ISNUMBER(I38),ISNUMBER(K38)),I38*K38,"") | N38: مازالت المنصة تجمع إحصائيات المنتج | O38: 143737
A39: 24 | B39: مجفف أحذية | C39: IQ030303MAGF99 | D39: 19000 | E39: 21000 | F39: 2000 | G39: 0.32 | H39: 4 | I39: 0.71 | J39: ممتاز | K39: 0.57 | L39: ممتاز | M39: =IF(AND(ISNUMBER(I39),ISNUMBER(K39)),I39*K39,"") -> 0.4047 | O39: 143046
A40: 25 | B40: صوبه منضدية مودكس | C40: IQ030401ASRS99 | D40: 25500 | E40: 28500 | F40: 3000 | J40: — | L40: — | M40: =IF(AND(ISNUMBER(I40),ISNUMBER(K40)),I40*K40,"") | N40: مازالت المنصة تجمع إحصائيات المنتج | O40: 143131
A41: 26 | B41: قفل باب ذكي Smart Lock | C41: IQ030303SMAR99 | D41: 59000 | E41: 61000 | F41: 2000 | J41: — | L41: — | M41: =IF(AND(ISNUMBER(I41),ISNUMBER(K41)),I41*K41,"") | N41: مازالت المنصة تجمع إحصائيات المنتج | O41: 143701
A43: =" الأسرّة الهوائية والمنافيخ · "&COUNTA(B44:B46)&" منتجات · السعر من "&TEXT(MIN(D44:D46),"#,##0")&" إلى "&TEXT(MAX(D44:D46),"#,##0")&" د.ع" -> الأسرّة الهوائية والمنافيخ · 3 منتجات · السعر من 41,000 إلى 62,500 د.ع
A44: 27 | B44: سرير هوائي قابل للنفخ Air Bed Single Size + منفاخ | C44: IQ030501BEDM99 | D44: 41000 | E44: 43000 | F44: 2000 | J44: — | L44: — | M44: =IF(AND(ISNUMBER(I44),ISNUMBER(K44)),I44*K44,"") | N44: مازالت المنصة تجمع إحصائيات المنتج · عرض مجمّع: IQ030103AIRS99 + IQ050202PUMP99 | O44: 143155
A45: 28 | B45: بلور هواء كبير شحن متعدد الاستخدامات | C45: IQ050402PLAH99 | D45: 48000 | E45: 50000 | F45: 2000 | I45: 0.76 | J45: ممتاز | L45: — | M45: =IF(AND(ISNUMBER(I45),ISNUMBER(K45)),I45*K45,"") | O45: 144332
A46: 29 | B46: سرير هوائي قابل للنفخ Air Bed Double Size | C46: IQ030103BEDF99 | D46: 62500 | E46: 65500 | F46: 3000 | J46: — | L46: — | M46: =IF(AND(ISNUMBER(I46),ISNUMBER(K46)),I46*K46,"") | N46: مازالت المنصة تجمع إحصائيات المنتج | O46: 143123
A48: =" أثاث وتخييم · "&COUNTA(B49:B50)&" منتجات · السعر من "&TEXT(MIN(D49:D50),"#,##0")&" إلى "&TEXT(MAX(D49:D50),"#,##0")&" د.ع" -> أثاث وتخييم · 2 منتجات · السعر من 72,000 إلى 81,000 د.ع
...

Sheet Sheet1
A1: مكنسة تنظيف منزلي Acarid Remover | B1: IQ030101ACRI99 | C1: 18,000 د.ع | D1: 21,000 د.ع | E1: 3,000 د.ع | F1: 0.03 | G1: 4 قطع | H1: 0.83 | I1: ممتاز | J1: 0.71 | K1: ممتاز | L1: 0.59
A2: المكنسة القابلة لإعادة الشحن الحديثة 3 في 1 | B2: IQ030303MSSK99 | C2: 33,000 د.ع | D2: 36,000 د.ع | E2: 3,000 د.ع | H2: 0.79 | I2: ممتاز | K2: —
A3: 4 | B3: مكنسة روبوت Smart Home ضمان 6 أشهر | C3: IQ030303ROHM99 | D3: 36,000 د.ع | E3: 39,000 د.ع | F3: 3,000 د.ع | I3: 0.63 | J3: ممتاز | L3: —
A4: 9 | B4: جهاز تنظيف بالبخار بالضغط العالي | C4: IQ030401BOHK99 | D4: 37,000 د.ع | E4: 40,000 د.ع | F4: 3,000 د.ع | G4: 0.12 | H4: 4 قطع | I4: 0.5 | J4: جيد | K4: 0.62 | L4: ممتاز | M4: 0.31
A5: خلاط Silver Crest + طاحونة ضمان 6 أشهر | B5: IQ030401CILV99 | C5: 26,500 د.ع | D5: 28,500 د.ع | E5: 2,000 د.ع | F5: 0.23 | G5: 2 قطع | H5: 0.56 | I5: جيد | J5: 0.62 | K5: ممتاز | L5: 0.35
A6: محضرة الطعام Olympia أكبر حجم 8 لتر | B6: IQ030401ALMN99 | C6: 39,000 د.ع | D6: 41,000 د.ع | E6: 2,000 د.ع | F6: 0.31 | G6: 3 قطع | H6: 0.53 | I6: جيد | J6: 0.69 | K6: ممتاز | L6: 0.37
A7: محضرة الطعام Olympia 8 لتر + ضمان 6 شهور (عرض مجمّع) | B7: IQ030501MNOI99 | C7: 43,000 د.ع | D7: 45,000 د.ع | E7: 2,000 د.ع | I7: — | K7: —
A8: 22 | B8: غالق الأبواب السحري | C8: IQ030303KHLK99 | D8: 11,500 د.ع | E8: 11,500 د.ع | F8: - | G8: 0.52 | H8: 4 قطع | J8: — | L8: —
A9: 24 | B9: مجفف أحذية | C9: IQ030303MAGF99 | D9: 19,000 د.ع | E9: 21,000 د.ع | F9: 2,000 د.ع | G9: 0.32 | H9: 4 قطع | I9: 0.71 | J9: ممتاز | K9: 0.57 | L9: ممتاز | M9: 0.4
A10: شاحن بطارية سيارة و الموبايل مع منفاخ للإطارات | B10: IQ050101JZQP99 | C10: 53,500 د.ع | D10: 58,500 د.ع | E10: 5,000 د.ع | H10: 0.63 | I10: ممتاز | J10: 0.5 | K10: ممتاز | L10: 0.32
A11: قفل سيارة ذكي للباركينج | B11: IQ050101AUTO99 | C11: 90,000 د.ع | D11: 95,000 د.ع | E11: 5,000 د.ع | H11: 0.71 | I11: ممتاز | J11: 0.4 | K11: جيد | L11: 0.28 | M11: ✅

Sheet ملخص المجموعات
A1: ملخص المجموعات
A3: المجموعة | B3: عدد المنتجات | C3: أقل سعر | D3: أعلى سعر | E3: متوسط السعر | F3: منتجات ليها إحصائيات | G3: أعلى نسبة تأكيد | H3: أعلى نسبة توصيل | I3: أعلى تسليم متوقع
A4: المكانس الكهربائية | B4: =COUNTA(المنتجات!B6:B13) -> 8 | C4: =MIN(المنتجات!D6:D13) -> 18000 | D4: =MAX(المنتجات!D6:D13) -> 101000 | E4: =AVERAGE(المنتجات!D6:D13) -> 48937.5 | F4: =COUNT(المنتجات!I6:I13)+SUMPRODUCT(--NOT(ISNUMBER(المنتجات!I6:I13)),--ISNUMBER(المنتجات!K6:K13)) -> 4 | G4: =IF(COUNT(المنتجات!I6:I13)=0,"-",MAX(المنتجات!I6:I13)) -> 0.83 | H4: =IF(COUNT(المنتجات!K6:K13)=0,"-",MAX(المنتجات!K6:K13)) -> 0.71 | I4: =IF(COUNT(المنتجات!M6:M13)=0,"-",MAX(المنتجات!M6:M13)) -> 0.5893
A5: أجهزة التنظيف بالبخار | B5: =COUNTA(المنتجات!B16:B17) -> 2 | C5: =MIN(المنتجات!D16:D17) -> 37000 | D5: =MAX(المنتجات!D16:D17) -> 47000 | E5: =AVERAGE(المنتجات!D16:D17) -> 42000 | F5: =COUNT(المنتجات!I16:I17)+SUMPRODUCT(--NOT(ISNUMBER(المنتجات!I16:I17)),--ISNUMBER(المنتجات!K16:K17)) -> 1 | G5: =IF(COUNT(المنتجات!I16:I17)=0,"-",MAX(المنتجات!I16:I17)) -> 0.5 | H5: =IF(COUNT(المنتجات!K16:K17)=0,"-",MAX(المنتجات!K16:K17)) -> 0.62 | I5: =IF(COUNT(المنتجات!M16:M17)=0,"-",MAX(المنتجات!M16:M17)) -> 0.31
A6: محضرات الطعام والخلاطات | B6: =COUNTA(المنتجات!B20:B23) -> 4 | C6: =MIN(المنتجات!D20:D23) -> 26500 | D6: =MAX(المنتجات!D20:D23) -> 88500 | E6: =AVERAGE(المنتجات!D20:D23) -> 49250 | F6: =COUNT(المنتجات!I20:I23)+SUMPRODUCT(--NOT(ISNUMBER(المنتجات!I20:I23)),--ISNUMBER(المنتجات!K20:K23)) -> 2 | G6: =IF(COUNT(المنتجات!I20:I23)=0,"-",MAX(المنتجات!I20:I23)) -> 0.56 | H6: =IF(COUNT(المنتجات!K20:K23)=0,"-",MAX(المنتجات!K20:K23)) -> 0.69 | I6: =IF(COUNT(المنتجات!M20:M23)=0,"-",MAX(المنتجات!M20:M23)) -> 0.3657
A7: المفارم والقطاعات | B7: =COUNTA(المنتجات!B26:B30) -> 5 | C7: =MIN(المنتجات!D26:D30) -> 21000 | D7: =MAX(المنتجات!D26:D30) -> 59000 | E7: =AVERAGE(المنتجات!D26:D30) -> 36500 | F7: =COUNT(المنتجات!I26:I30)+SUMPRODUCT(--NOT(ISNUMBER(المنتجات!I26:I30)),--ISNUMBER(المنتجات!K26:K30)) -> 3 | G7: =IF(COUNT(المنتجات!I26:I30)=0,"-",MAX(المنتجات!I26:I30)) -> 0.63 | H7: =IF(COUNT(المنتجات!K26:K30)=0,"-",MAX(المنتجات!K26:K30)) -> 0.67 | I7: =IF(COUNT(المنتجات!M26:M30)=0,"-",MAX(المنتجات!M26:M30)) -> 0.4221
A8: أجهزة مطبخ أخرى | B8: =COUNTA(المنتجات!B33:B34) -> 2 | C8: =MIN(المنتجات!D33:D34) -> 29000 | D8: =MAX(المنتجات!D33:D34) -> 60000 | E8: =AVERAGE(المنتجات!D33:D34) -> 44500 | F8: =COUNT(المنتجات!I33:I34)+SUMPRODUCT(--NOT(ISNUMBER(المنتجات!I33:I34)),--ISNUMBER(المنتجات!K33:K34)) -> 0 | G8: =IF(COUNT(المنتجات!I33:I34)=0,"-",MAX(المنتجات!I33:I34)) -> - | H8: =IF(COUNT(المنتجات!K33:K34)=0,"-",MAX(المنتجات!K33:K34)) -> - | I8: =IF(COUNT(المنتجات!M33:M34)=0,"-",MAX(المنتجات!M33:M34)) -> -
A9: منزل متنوع | B9: =COUNTA(المنتجات!B37:B41) -> 5 | C9: =MIN(المنتجات!D37:D41) -> 11500 | D9: =MAX(المنتجات!D37:D41) -> 59000 | E9: =AVERAGE(المنتجات!D37:D41) -> 26200 | F9: =COUNT(المنتجات!I37:I41)+SUMPRODUCT(--NOT(ISNUMBER(المنتجات!I37:I41)),--ISNUMBER(المنتجات!K37:K41)) -> 1 | G9: =IF(COUNT(المنتجات!I37:I41)=0,"-",MAX(المنتجات!I37:I41)) -> 0.71 | H9: =IF(COUNT(المنتجات!K37:K41)=0,"-",MAX(المنتجات!K37:K41)) -> 0.57 | I9: =IF(COUNT(المنتجات!M37:M41)=0,"-",MAX(المنتجات!M37:M41)) -> 0.4047
A10: الأسرّة الهوائية والمنافيخ | B10: =COUNTA(المنتجات!B44:B46) -> 3 | C10: =MIN(المنتجات!D44:D46) -> 41000 | D10: =MAX(المنتجات!D44:D46) -> 62500 | E10: =AVERAGE(المنتجات!D44:D46) -> 50500 | F10: =COUNT(المنتجات!I44:I46)+SUMPRODUCT(--NOT(ISNUMBER(المنتجات!I44:I46)),--ISNUMBER(المنتجات!K44:K46)) -> 1 | G10: =IF(COUNT(المنتجات!I44:I46)=0,"-",MAX(المنتجات!I44:I46)) -> 0.76 | H10: =IF(COUNT(المنتجات!K44:K46)=0,"-",MAX(المنتجات!K44:K46)) -> - | I10: =IF(COUNT(المنتجات!M44:M46)=0,"-",MAX(المنتجات!M44:M46)) -> -
A11: أثاث وتخييم | B11: =COUNTA(المنتجات!B49:B50) -> 2 | C11: =MIN(المنتجات!D49:D50) -> 72000 | D11: =MAX(المنتجات!D49:D50) -> 81000 | E11: =AVERAGE(المنتجات!D49:D50) -> 76500 | F11: =COUNT(المنتجات!I49:I50)+SUMPRODUCT(--NOT(ISNUMBER(المنتجات!I49:I50)),--ISNUMBER(المنتجات!K49:K50)) -> 0 | G11: =IF(COUNT(المنتجات!I49:I50)=0,"-",MAX(المنتجات!I49:I50)) -> - | H11: =IF(COUNT(المنتجات!K49:K50)=0,"-",MAX(المنتجات!K49:K50)) -> - | I11: =IF(COUNT(المنتجات!M49:M50)=0,"-",MAX(المنتجات!M49:M50)) -> -
A12: الطاقة الشمسية | B12: =COUNTA(المنتجات!B53:B56) -> 4 | C12: =MIN(المنتجات!D53:D56) -> 22000 | D12: =MAX(المنتجات!D53:D56) -> 212000 | E12: =AVERAGE(المنتجات!D53:D56) -> 75000 | F12: =COUNT(المنتجات!I53:I56)+SUMPRODUCT(--NOT(ISNUMBER(المنتجات!I53:I56)),--ISNUMBER(المنتجات!K53:K56)) -> 1 | G12: =IF(COUNT(المنتجات!I53:I56)=0,"-",MAX(المنتجات!I53:I56)) -> 0.54 | H12: =IF(COUNT(المنتجات!K53:K56)=0,"-",MAX(المنتجات!K53:K56)) -> 0.41 | I12: =IF(COUNT(المنتجات!M53:M56)=0,"-",MAX(المنتجات!M53:M56)) -> 0.2214
A13: السيارات (داش كام وإكسسوارات) | B13: =COUNTA(المنتجات!B59:B64) -> 6 | C13: =MIN(المنتجات!D59:D64) -> 30000 | D13: =MAX(المنتجات!D59:D64) -> 90000 | E13: =AVERAGE(المنتجات!D59:D64) -> 50000 | F13: =COUNT(المنتجات!I59:I64)+SUMPRODUCT(--NOT(ISNUMBER(المنتجات!I59:I64)),--ISNUMBER(المنتجات!K59:K64)) -> 6 | G13: =IF(COUNT(المنتجات!I59:I64)=0,"-",MAX(المنتجات!I59:I64)) -> 0.71 | H13: =IF(COUNT(المنتجات!K59:K64)=0,"-",MAX(المنتجات!K59:K64)) -> 0.5 | I13: =IF(COUNT(المنتجات!M59:M64)=0,"-",MAX(المنتجات!M59:M64)) -> 0.315
A14: إلكترونيات وتقنية | B14: =COUNTA(المنتجات!B67:B70) -> 4 | C14: =MIN(المنتجات!D67:D70) -> 17000 | D14: =MAX(المنتجات!D67:D70) -> 38500 | E14: =AVERAGE(المنتجات!D67:D70) -> 29750 | F14: =COUNT(المنتجات!I67:I70)+SUMPRODUCT(--NOT(ISNUMBER(المنتجات!I67:I70)),--ISNUMBER(المنتجات!K67:K70)) -> 1 | G14: =IF(COUNT(المنتجات!I67:I70)=0,"-",MAX(المنتجات!I67:I70)) -> - | H14: =IF(COUNT(المنتجات!K67:K70)=0,"-",MAX(المنتجات!K67:K70)) -> 0.67 | I14: =IF(COUNT(المنتجات!M67:M70)=0,"-",MAX(المنتجات!M67:M70)) -> -
A15: العزل والصيانة | B15: =COUNTA(المنتجات!B73:B74) -> 2 | C15: =MIN(المنتجات!D73:D74) -> 14000 | D15: =MAX(المنتجات!D73:D74) -> 15500 | E15: =AVERAGE(المنتجات!D73:D74) -> 14750 | F15: =COUNT(المنتجات!I73:I74)+SUMPRODUCT(--NOT(ISNUMBER(المنتجات!I73:I74)),--ISNUMBER(المنتجات!K73:K74)) -> 0 | G15: =IF(COUNT(المنتجات!I73:I74)=0,"-",MAX(المنتجات!I73:I74)) -> - | H15: =IF(COUNT(المنتجات!K73:K74)=0,"-",MAX(المنتجات!K73:K74)) -> - | I15: =IF(COUNT(المنتجات!M73:M74)=0,"-",MAX(المنتجات!M73:M74)) -> -
A16: الإجمالي | B16: =SUM(B4:B15) -> 47 | C16: =MIN(C4:C15) -> 11500 | D16: =MAX(D4:D15) -> 212000 | E16: =AVERAGE(المنتجات!D5:D74) -> 45276.596 | F16: =SUM(F4:F15) -> 20 | G16: =MAX(G4:G15) -> 0.83 | H16: =MAX(H4:H15) -> 0.71 | I16: =MAX(I4:I15) -> 0.5893
